{"uuid": "a8c08cdd-c132-4ca4-96d2-e0b572505713", "children": ["3a075107-4006-40fb-9d1c-25df3e94b7c5", "ad506615-b3fc-4329-8352-0522c7f49454", "98f4c704-286c-475a-86c7-6108c2e767fd", "b214e89e-03e6-45f1-b1a1-85ff10bb17b5", "dac7414a-8d07-4c81-82bd-b913737c02c9", "0710e827-cc8e-4790-95db-24a5375e57c9", "54dc3720-cb8a-4f7f-ad09-a7fdc12acf72", "2ada924e-3438-4877-bf04-439d41e07280", "f8e675e5-9945-45d1-b65a-e0308fc75a50", "6947fbc3-8f49-4c29-95ea-c5245fc13a0e", "2b476b14-d919-44e8-af4b-643c73761abd", "8104315d-096e-465a-8969-21ad9cb86fc0", "105849c4-5cee-4663-b906-b7d0606ae5c6"], "befores": [{"name": "xunit_setup_class_fixture_TestLogin", "status": "broken", "statusDetails": {"message": "urllib3.exceptions.MaxRetryError: HTTPConnectionPool(host='127.0.0.1', port=4723): Max retries exceeded with url: /wd/hub/session (Caused by NewConnectionError('<urllib3.connection.HTTPConnection object at 0x11383b748>: Failed to establish a new connection: [Errno 61] Connection refused',))\n", "trace": "  File \"/Library/Frameworks/Python.framework/Versions/3.6/lib/python3.6/site-packages/pluggy/callers.py\", line 187, in _multicall\n    res = hook_impl.function(*args)\n  File \"/Library/Frameworks/Python.framework/Versions/3.6/lib/python3.6/site-packages/_pytest/fixtures.py\", line 1126, in pytest_fixture_setup\n    result = call_fixture_func(fixturefunc, request, kwargs)\n  File \"/Library/Frameworks/Python.framework/Versions/3.6/lib/python3.6/site-packages/_pytest/fixtures.py\", line 925, in call_fixture_func\n    fixture_result = next(generator)\n  File \"/Library/Frameworks/Python.framework/Versions/3.6/lib/python3.6/site-packages/_pytest/python.py\", line 811, in xunit_setup_class_fixture\n    _call_with_optional_argument(func, self.obj)\n  File \"/Library/Frameworks/Python.framework/Versions/3.6/lib/python3.6/site-packages/_pytest/python.py\", line 739, in _call_with_optional_argument\n    func(arg)\n  File \"/Users/yixia/PycharmProjects/iosmiaopai/testCase/IMP_login.py\", line 238, in setup_class\n    desired_caps)\n  File \"/Library/Frameworks/Python.framework/Versions/3.6/lib/python3.6/site-packages/appium/webdriver/webdriver.py\", line 155, in __init__\n    proxy\n  File \"/Library/Frameworks/Python.framework/Versions/3.6/lib/python3.6/site-packages/selenium/webdriver/remote/webdriver.py\", line 157, in __init__\n    self.start_session(capabilities, browser_profile)\n  File \"/Library/Frameworks/Python.framework/Versions/3.6/lib/python3.6/site-packages/appium/webdriver/webdriver.py\", line 225, in start_session\n    response = self.execute(RemoteCommand.NEW_SESSION, parameters)\n  File \"/Library/Frameworks/Python.framework/Versions/3.6/lib/python3.6/site-packages/selenium/webdriver/remote/webdriver.py\", line 319, in execute\n    response = self.command_executor.execute(driver_command, params)\n  File \"/Library/Frameworks/Python.framework/Versions/3.6/lib/python3.6/site-packages/selenium/webdriver/remote/remote_connection.py\", line 374, in execute\n    return self._request(command_info[0], url, body=data)\n  File \"/Library/Frameworks/Python.framework/Versions/3.6/lib/python3.6/site-packages/selenium/webdriver/remote/remote_connection.py\", line 397, in _request\n    resp = self._conn.request(method, url, body=body, headers=headers)\n  File \"/Library/Frameworks/Python.framework/Versions/3.6/lib/python3.6/site-packages/urllib3/request.py\", line 72, in request\n    **urlopen_kw)\n  File \"/Library/Frameworks/Python.framework/Versions/3.6/lib/python3.6/site-packages/urllib3/request.py\", line 150, in request_encode_body\n    return self.urlopen(method, url, **extra_kw)\n  File \"/Library/Frameworks/Python.framework/Versions/3.6/lib/python3.6/site-packages/urllib3/poolmanager.py\", line 324, in urlopen\n    response = conn.urlopen(method, u.request_uri, **kw)\n  File \"/Library/Frameworks/Python.framework/Versions/3.6/lib/python3.6/site-packages/urllib3/connectionpool.py\", line 667, in urlopen\n    **response_kw)\n  File \"/Library/Frameworks/Python.framework/Versions/3.6/lib/python3.6/site-packages/urllib3/connectionpool.py\", line 667, in urlopen\n    **response_kw)\n  File \"/Library/Frameworks/Python.framework/Versions/3.6/lib/python3.6/site-packages/urllib3/connectionpool.py\", line 667, in urlopen\n    **response_kw)\n  File \"/Library/Frameworks/Python.framework/Versions/3.6/lib/python3.6/site-packages/urllib3/connectionpool.py\", line 638, in urlopen\n    _stacktrace=sys.exc_info()[2])\n  File \"/Library/Frameworks/Python.framework/Versions/3.6/lib/python3.6/site-packages/urllib3/util/retry.py\", line 399, in increment\n    raise MaxRetryError(_pool, url, error or ResponseError(cause))\n"}, "start": 1619403915810, "stop": 1619403915839}], "start": 1619403915810, "stop": 1619403918196}