{"uuid": "cf104152-477b-4693-926a-b23142f5bcf4", "children": ["aca39848-1403-405b-a5a6-fa7d7e3fb380"], "befores": [{"name": "xunit_setup_class_fixture_TestLogin", "status": "broken", "statusDetails": {"message": "selenium.common.exceptions.WebDriverException: Message: An unknown server-side error occurred while processing the command. Original error: Unknown device or simulator UDID: '00008020-00022D683688002E'\n\n", "trace": "  File \"/Library/Frameworks/Python.framework/Versions/3.6/lib/python3.6/site-packages/pluggy/callers.py\", line 187, in _multicall\n    res = hook_impl.function(*args)\n  File \"/Library/Frameworks/Python.framework/Versions/3.6/lib/python3.6/site-packages/_pytest/fixtures.py\", line 1126, in pytest_fixture_setup\n    result = call_fixture_func(fixturefunc, request, kwargs)\n  File \"/Library/Frameworks/Python.framework/Versions/3.6/lib/python3.6/site-packages/_pytest/fixtures.py\", line 925, in call_fixture_func\n    fixture_result = next(generator)\n  File \"/Library/Frameworks/Python.framework/Versions/3.6/lib/python3.6/site-packages/_pytest/python.py\", line 811, in xunit_setup_class_fixture\n    _call_with_optional_argument(func, self.obj)\n  File \"/Library/Frameworks/Python.framework/Versions/3.6/lib/python3.6/site-packages/_pytest/python.py\", line 739, in _call_with_optional_argument\n    func(arg)\n  File \"/Users/yixia/PycharmProjects/iosmiaopai/testCase/IMP_login.py\", line 295, in setup_class\n    desired_caps)\n  File \"/Library/Frameworks/Python.framework/Versions/3.6/lib/python3.6/site-packages/appium/webdriver/webdriver.py\", line 155, in __init__\n    proxy\n  File \"/Library/Frameworks/Python.framework/Versions/3.6/lib/python3.6/site-packages/selenium/webdriver/remote/webdriver.py\", line 157, in __init__\n    self.start_session(capabilities, browser_profile)\n  File \"/Library/Frameworks/Python.framework/Versions/3.6/lib/python3.6/site-packages/appium/webdriver/webdriver.py\", line 225, in start_session\n    response = self.execute(RemoteCommand.NEW_SESSION, parameters)\n  File \"/Library/Frameworks/Python.framework/Versions/3.6/lib/python3.6/site-packages/selenium/webdriver/remote/webdriver.py\", line 321, in execute\n    self.error_handler.check_response(response)\n  File \"/Library/Frameworks/Python.framework/Versions/3.6/lib/python3.6/site-packages/selenium/webdriver/remote/errorhandler.py\", line 242, in check_response\n    raise exception_class(message, screen, stacktrace)\n"}, "start": 1619430095392, "stop": 1619430095971}], "start": 1619430095392, "stop": 1619430096312}